<!DOCTYPE html>
<html lang="en">
<head>
  <meta charset="UTF-8">
  <title>Title</title>
</head>
<body>
<script>
/* Promise 是一个对象, 从它可以获取异步操作的消息, 是异步编程的一种解决方案, 比传统的解决方案:回调函数和事件, 更合理和强大
*   Promise简单来说是一个容器, 里面保存着某个未来才会结束的事件, 通常是一个异步操作的结果
*   有两个特点:
*     1. 对象的状态不受外界影响, Promise对象代表一个异步操作, 有三种状态: pending(进行中), fulfilled(已成功), reject(已失败)
*   只有异步操作的结果可以决定当前是哪一种状态, 其他任何操作都无法改变这个状态
*     2. 一旦状态改变, 就不会再变, 任何时候都可以得到这个结果, Promise的对象的状态改变只有两种可能, 从pending变成fulfilled和从pending变成rejected
*   , 只要这两种情况发生了, 状态就会一直保持这个结果不再改变, 此时称为resolved(已定型), 如果改变已经发生了, 再对Promise对象添加回调函数, 也会立即得到这个结果
*   , 与事件(event)完全不同, 事件错过后再去监听是得不到结果的
*
*   有了Promise对象, 就可以将异步操作以同步操作的流程表达, 避免了层层嵌套的回调函数, 此外Promise提供了统一的接口, 使得异步操作更加容易
*
*   Promise也有一些缺点:
*     1. 无法取消Promise, 一旦新建就会立即执行
*     2. Promise如果不设置回调函数, 内部抛出的错误不会反应到外部
*     3. 当处于pending状态时无法得知目前进展到哪一阶段
* */

/* ES6规定Promise对象是一个构造函数, 用来生成Promise实例 */
const promise = new Promise(function(resolve, reject) {
  // ... some code
  if ("异步操作成功") {
    resolve(value)
  } else {
    reject(error)
  }
})
/* Promise构造函数接收一个函数作为参数, 该函数的两个参数分别是resolve 和reject ,是两个函数, 又JS引擎提供, 无需自己部署
*   resolve函数的作用是, 将Promise对象的状态从pending变成fulfilled, 在异步操作成功时调用, 并将异步操作的结果作为参数传递出去
*   reject函数的作用同理, 将Promise对象的状态从pending变成rejected, 在异步操作失败时调用, 并将异步操作报出的错误作为参数传递出去
*  */
promise.then(function (value) {
  // success
}, function (error) {
  // failure
})
/* then方法接收两个回调函数作为参数, 第一个回调函数是Promise对象的状态变为fulfilled的时候调用, 第二个函数是Promise对象的状态变成rejected的时候调用
* 这两个函数都是可选的, 不一定需要提供, 它们均接收Promise对象传出的值作为参数
* */
// 一个简单的Promise对象的例子
function timeout(ms) {
  return new Promise((resolve, reject) => {
    setTimeout(resolve, ms, 'done')
  })
}
  /* 其中, setTimeout()函数只有两个参数, 第一个参数是必填的将要执行的函数表达式, 此处为resolve; 第二个参数为必填的等待的时间毫秒数;
  从第三个参数开始后面的所有参数都是函数表达式的参数, 因此此处'done'实际是resolve的参数*/
timeout(100).then((value) => {
  console.log(value)
})
/* 上例timeout函数返回一个Promise实例, 表示一段时间后才会发生的结果, 过了指定时间(ms)后, Promise实例的状态变为resolved, 就会触发then方法绑定的回调函数 */

/* Promise新建后就会立即执行 */
let promise2 = new Promise(function(resolve, reject) {
  console.log('Promise')
  resolve()
})
promise.then(function (){
  console.log('resolved.')
})
console.log('Hi')
// Promise
// Hi
// resolved.
/* 上述代码中, Promise新建后立即执行, 所以首先输出的是Promise, 然后then方法指定的回调函数将在当前脚本所有同步任务执行完之后才会执行, 所以resolve最后输出 */
// 例子1 异步加载图片
function loadImageAsync(url) {
  return new Promise(function (resolve, reject) {
    const image = new Image()
    image.onload = function() {
      resolve(image)
    }
    image.onerror = function() {
      reject(new Error('Could not load image at ' + url))
    }
    image.src = url
  })
}
/* 上面的代码中 使用Promise包装了一个图片加载的异步操作, 如果加载成功, 就调用resolve方法, 否则就调用reject方法 */
// 例子2: 使用Promise实现的Ajax操作的例子
const getJSON = function(url) {
  const promise = new Promise(function(resolve, reject) {
    const handler = function () {
      if (this.readyState !== 4) {
        return
      }
      if (this.status === 200) {
        resolve(this.response)
      } else {
        reject(new Error(this.statusText))
      }
    }
    const client = new XMLHttpRequest()
    client.open('Get', url)
    client.onreadystatechange = handler
    client.responseType = "json"
    client.setRequestHeader("accept","application/json")
    client.send()
  })
  return promise
}
getJSON("/posts.json").then(function(json) {
  console.log('Content: ' + json)
}, function(error) {
  console.error('出错了', error)
})
/*  上面的代码中, getJSON是对XMLHttpRequest对象的封装, 用于发出一个针对JSON数据的HTTP请求, 并且返回一个Promise对象; 需要注意的是在getJSON内部
* , resolve函数和reject函数调用时都带有参数
*   当调用resolve和reject时带有参数, 那么他们的参数会被传递给回调函数, reject函数的参数通常是Error对象的实例 , 表示抛出的错误;
* 而resolve函数的参数除了正常的值以外, 还可能是另一个Promise实例
*/
const p1 = new Promise(function (resolve, reject) {
  // ...
})
const p2 = new Promise(function (resolve, reject) {
  // ...
  resolve(p1)
})
/* 上面代码中, p1和p2都是Promise实例, 但是p2的resolve方法将p1作为参数, 即一个异步操作的结果是返回另一个异步操作
*   这时的p1状态就会传递给p2, 也就是说, p1的状态决定了p2的状态, 如果p1的状态是pending, 那么p2的回调函数就会等待p1的状态改变, 如果p1的状态
* 已经是resolved或者rejected, 那么p2的回调函数将会立即执行
* */
const p3 = new Promise(function (resolve, reject) {
  setTimeout(() => reject(new Error('fail')), 3000)
})
const p4 = new Promise(function (resolve, reject) {
  setTimeout(() => resolve(p3), 1000)
})
p4
  .then(result => console.log(result))
  .catch(error => console.log(error))
// Error: fail
/*  上述代码中, p3是一个Promise, 3秒后变为reject, p4的状态在1秒后改变, resolve方法返回的是p3, 由于p4返回的是另一个Promise, 导致p4自己的状态无效了
* 由p3的状态决定p4的状态, 所以后面的then语句都变成针对后者(p3), 又过了2秒, p3变为rejected, 导致触发catch方法指定的回调函数
*   注意: 调用resolve或reject方法并不会终结Promise的参数的执行
*  */

new Promise((resolve, reject) => {
  resolve(1)
  console.log(2)
}).then (r => {
  console.log(r)
})
// 2
// 1
/*  上述代码中, 调用resolve(1)后, 后面你的console(2)还是会执行, 并且会首先打印出来, 这是因为立即resolve的Promise是在本轮事件循环的末尾执行
* ,总是晚于本轮循环的同步任务
*   一般来说, 调用resolve或reject方法之后, Promise的使命就完成了, 后续操作应放到then方法中, 而不应该直接写在resolve或reject的后面, 所以
* 最好在它们的前面加上return语句, 这样就不会有以外了
*  */
new Promise((resolve, reject) => {
  return resolve(1)
  // 后面的语句不会执行
  console.log(2)
}).then (r => {
  console.log(r)
})

/* Promise.prototype.then()
*   Promise实例具有then方法, 也就是说, then方法是定义在原型对象Promise.prototype上的, 它的作用是为Promise实例添加状态改变时的回调函数;
* 前面提到, then方法的第一个参数是resolved状态的回调函数, 第二个参数是rejected状态的回调函数, 它们都是可选的
*   then方法返回的是一个新的Promise实例(非原来那个), 因此可以采用链式写法, then方法后面再调用另一个then方法
*  */
getJSON("/post/1.json").then(function(post) {
  return getJSON(post.commentURL)
}).then(function (comments) {
  console.log("resolved: ", comments)
},function (error) {
  console.log("rejected: ", error)
})
/*  上述代码中, 第一个then方法指定的回调函数, 返回的是另一个Promise对象, 这时, 第二个then方法指定的回调函数就会等待这个新的Promise对象发生状态变化
* , 如果变为resolved,就调用第一个回调函数, 如果状态变为rejected, 就调用第二个回调函数
*  */
// 采用箭头函数更加简洁
getJSON("/post/1.json").then(function(post) {
  post => getJSON(post.commentURL)
}).then(
  comments => console.log("resolved: ", comments),
  error  => console.log("rejected: ", error)
)

/* Promise.prototype.catch()
*   首先要区分一点的就是then的第二个参数reject是用来抛出异常的,而catch是用来处理异常的
*   reject是Promise的方法而then和catch是Promise实例的方法, 且如果在then的第一个函数里抛出了异常, then的第二个参数捕获不到, 但catch能捕获到
*   catch只是一个语法糖而已, 实际上还是通过then来处理, 大概为
*     Promise.prototype.catch = function(fn) { return this.then(null, fn) }
*   then的第二个参数和catch捕获错误信息的时候会就近原则, 如果是Promise内部报错, reject抛出错误后, then的第二个参数和catch方法都存在的情况下
* ,只有then的第二个参数能捕获到, 如果then的第二个参数不存在, 那么catch方法可以捕获到
*
*   Promise.prototype.catch()方法是.then(null, rejection)或.then(undefined, rejection)的别名, 用于指定发生错误时的回调函数
*  */
getJSON('/posts.json').then(function(posts) {
  // ...
}).catch (function (error) {
  // 处理getJSON和前一个回调函数运行时发生的错误
  console.log('发生错误! ', error)
})
/*  上述代码中, getJSON() 方法返回一个Promise对象, 如果该对象状态变为resolved, 则会调用then() 方法指定的回调函数, 如果异步操作抛出错误,
* 状态就会变为rejected, 就会调用catch() 的方法指定的回调函数处理这个错误, 另外, then()方法指定的回调函数如果在运行中出现错误, 也会被catch方法()捕获
*  */

/* reject()方法作用, 等同于抛出错误, 如果Promise的状态已经变为resolved, 再抛出错误是无效的 */
const promise2 = new Promise(function (resolve, reject) {
  resolve('OK')
  throw new Error('test')
})
promise2
  .then(function(value) { console.log(value) })
  .catch(function(error) { console.log(error) })
/* 上述代码中, Promise在resolve语句的后面, 再抛出错误就不会被捕获, 等于没有抛出错误, 因为Promise的状态一但改变就永久个改变了 */

/* Promise对象的错误具有冒泡性质, 会一直向后传递, 直到被捕获为止, 也就是说错误总是会被下一个catch捕获到 */
getJSON('/post/1.json').then(function(post) {
  return getJSON(post.commentURL)
}).then(function (comment) {
  //...
}).catch(function (error) {
  // 处理前面三个Promise产生的错误
})
/* 上述代码一共有三个Promise对象, 一个由getJSON()产生, 两个由then()产生, 它们之中的任何一个抛出错误, 都会被最后一个catch捕获到 */

/* 一般来说, 不要在then()方法里面法定义Reject状态的回调函数(即then的第二个参数), 总是使用catch方法 */
// 不好的写法
promise
  .then(function(data) {
    // success
  }, function (error) {
    // error
  })
// 好的写法
promise
  .then(function (data) {
    // success
  })
  .catch(function(err) {
    // error
  })
/*  上述写法, 第二种明显优于第一种, 第二种写法可以捕获前面then方法执行中的错误, 也更接近同步的写法(try/catch)
* 因此, 总是建议使用catch()方法, 而不是使用then()方法的第二个参数 */

/*  与传统的try/ catch方法不同, 如果不使用一个catch去指定错误处理的回调函数, 则Promise对象抛出的错误不会船夫到外层代码, 即不会有任何反应 */
const someAsyncThing = function () {
  return new Promise(function (resolve, reject) {
    // 下面一行报错, x没有声明
    resolve(x + 2)
  })
}
someAsyncThing().then(function () {
  console.log('everything is great')
})
setTimeout(() => {console.log(123)}, 2000)
// Uncaught (in promise) ReferenceError: x is not defined
/*  上述代码中, someAsyncThing() 函数产生的Promise对象, 内部有语法错误, 浏览器运行到这一行会打印出错误提示, 但是不会退出进程和终止脚本进行,
* 两秒后还是会输出123, 也就是说Promise内部的错误不会影响到Promise外部的代码. 'Promise会吃掉错误'
*   一般总是建议, Promise对象后要跟catch()方法, 这样可以处理Promise内部发生的错误, catch()方法返回的还是一个Promise对象, 因此后面还可以接着调用then方法
* */

/* Promise.prototype.finally
*   finally()方法用于指定不管Promise对象最后状态如何, 都会执行的操作
*  */
promise
  .then(result => {})
  .catch(error => {})
  .finally(() => {})
/* 上述代码物无论promise最后的状态如何, 在执行完try或catch指定的回调函数后, 都会执行finally方法指定的回调函数 */
// 例子: 服务器使用Promise处理请求, 然后使用finally方法关掉服务器
server.listen(port)
  .then(function () {
    // ...
  })
  .finally(server.stop)
/* finally方法的回调函数不接受任何参数, 这意味着没法得知前面的Promise状态到底是fulfilled还是rejected, 这表明finally()方法里的操作应当与状态无关
* ,不依赖于Promise的执行结果 */
/* finally本质上也是then方法的特例 */
promise
  .finally(() => {
    // 语句
  })
  // 等同于
  promise
  .then(
    result => {
      // 语句
      return result
    },
    error => {
      // 语句
      throw error
    }
  )
/* 上述代码如果不使用finally方法, 同样的语句需要为成功或者失败两种情况各写一次 */
// finally实现
Promise.prototype.finally = function (callback) {
  let P = this.constructor
  return this.then(
    value => P.resolve(callback()).then(() => value),
    reason => P.resolve(callback()).then(() =>{throw reason})
  )
}
/* 上面代码中, 不管前面的Promise是fulfilled还是rejected, 都会执行回调函数callback, finally方法总是会返回原来的值 */

/* Promise.all()
*   该方法用于将多个Promise实例包装成一个全新的Promise实例
*  */
const p = Promise.all([p1, p2, p3])
/*  上面代码中, Promise.all()方法接收一个数组作为参数, p1, p2, p3都是Promise实例, 如果不是就会先调用后面说到的Promise.resolve()方法
* 将参数转化为Promise实例, 再进一步处理, 另外, Promise.all()方法的参数可以不是数组, 但必须具有Iterator接口, 且返回的每个成员都是Promise实例
*   p的状态由p1, p2, p3决定, 分层两种情况
*     (1) 只有p1, p2, p3的状态都变成fulfilled, p的状态才会变成fulfilled, 此时p1, p2, p3的返回值组成一个数组, 返回给p的回调函数
*     (2) 只要p1, p2, p3中有一个被rejected, p的状态就变成rejected, 此时第一个被reject的实例的返回值会传递给p的回调函数
*  */
// 例子
  // 生成一个Promise对象的数组
  const promises = [2, 3, 5, 7, 11, 13].map(function (id) {
    return getJSON('/post/' + id + ".json")
  })
  Promise.all(promises).then(function (posts) {
    // ...
  }).catch(function (reason) {
    // ...
  })
/* 上述代码中, promises是包含6个Promise实例的数组, 只有这6个实例的状态都变fulfilled, 或者其中一个人变为rejected, 才会调用Promise.all方法后面的回调函数 */

/*  注意: 如果作为参数的Promise实例, 自已定义了catch方法, 那么即使它被rejected也不会触发Promise.all()的catch()方法 */

/* Promise.race()
*   Promise.race() 方法同样是将多个Promise实例包装成一个新的Promise实例
*  */
const ps = Promise.race([p1, p2, p3])
/*  上述代码只要p1, p2, p3之中有一个实例率先改变状态, p的状态就跟着改变, 那个率先改变的Promise实例的返回值, 就传递给p的回调函数
*   Promise.race()方法和Promise.all()方法一样, 如果不是Promise实例, 就会下调用后续讲的Promise.resolve()方法, 讲参数转换成Promise实例再进一步处理
*  */
// 例子: 如果指定时间内没有获得结果, 就将Promise的状态改变为reject
const p5 = Promise.race([
  fetch('/resource-that-may-take-a-while'),
  new Promise(function (resolve, reject) {
    setTimeout(() => reject(new Error('request timeout')), 5000)
  })
])
p
  .then(console.log)
  .catch(console.error)
/* 上述代码中, 如果5秒内fetch方法无法返回结果, 变量p的状态就会变为rejected, 从而触发catch方法指定的回调函数 */

/* Promise.allSettled()
*   有时候, 我们希望等到一组异步函数操作都结束了, 不管每一个 操作是成功还是失败, 再进行下一步操作, 但是现有的Promise方法很难实现这个需求
*   Promise.all()方法只适合所有异步函数都成功的情况, 如果有一个操作失败, 就无法满足要求
*   为了解决这个问题, 引入了Promise.allSettled() 方法, 用来确定一组异步操作是否都结束了(无论成功或失败), 所以名字叫Settled,包含fulfilled和rejected两种情况
*   Promise.allSettled()方法接收一个数组作为参数, 数组的每个成员都是一个Promise对象, 并返回一个新的Promise对象, 只有等到参数数组的每个对象都发生状态变化
* , 返回的Promise对象才会发生状态变更
*  */
const promises1 = [
  fetch('/api-1'),
  fetch('/api-2'),
  fetch('/api-3')
]
await Promise.allSettled(promises1)
removeLoadingIndicator()
/*  上面示例中, 数组promises1包含了三个请求, 只有等到这三个请求都结束了, removeLoadingIndicator()才会执行
*   该方法返回新的Promise实例, 一旦发生状态变更, 状态总是fulfilled, 不会变成rejected, 状态变成fulfilled, 它的回调函数会接收到一个数组作为参数
* , 该数组的每个成员对应前面数组的每个Promise对象
*  */
const resolved = Promise.resolve(42)
const rejected = Promise.reject(-1)

const allSettledPromise = Promise.allSettled([resolved, rejected])
allSettledPromise.then(function(result) {
  console.log(result)
})
  /* [
    { status: 'fulfilled', value: 42 }
    { status: 'rejected', reason: -1 }
  ] */
/*  上述代码中, Promise.allSettled()的返回值allSettledPromise, 状态只可能变成fulfilled, 他的回调函数接收到的参数是数组results
* ,该数组的每一个成员都是一个对象, 对应传如的Promise.allSettled()的数组里面的两个Promise对象 */
/* results中的  每个成员是一个对象, 对象的成员是固定的, 对应异步操作的结果 */
/* [
    // 异步操作成功时
    { status: 'fulfilled', value: 42 }
    // 异步操作失败时
    { status: 'rejected', reason: -1 }
] */
/*  成员对象的status属性的值只可能是字符串fulfilled或者rejected, 用来区分异步操作是成功还是失败, 如果是成功, 则对象会有value属性, 如果是失败, 会有reason属性
* ,对应前面两种状态时异步操作的返回值
*  */
// 过滤出成功的请求
const successfulPromises = results.filter(p => p.status === 'fulfilled')
// 过滤出失败的请求, 并输出原因
const errors = results
  .filter(p => p.status === 'rejected')
  .map(p => p.reason)

/* Promise.any()
*   该方法接收一组Promise实例作为参数, 包装成一个新的Promise实例返回
*   只要参数实例有一个变成fulfilled状态, 包装实例就会变成rejected状态, 如果所有参数实例都变成rejected状态, 包装实例才变为rejected状态
*   类似Promise.race()方法, 但不同的是Promise.any()不会因为某个Promise变成rejected状态而结束, 必须等到所有参数Promise都变成rejected状态才会结束
*  */
// Promise() 和await命令结合使用的例子
const promises2 = [
  fetch('/endpoint-a').then(() => 'a'),
  fetch('/endpoint-b').then(() => 'b'),
  fetch('/endpoint-c').then(() => 'c')
]
try {
  const first = await Promise.any(promises2)
  console.log(first)
} catch(error) {
  console.log(error)
}
/*  上述方法中, Promise.any()方法的参数包含三个Promise操作, 其中只要有一个变成fulfilled, Promise.any()返回的Promise对象就变成fulfilled
* ,如果所有三个操作都变成rejected, 那么await命令就会抛出错误
*   Promise.any()抛出的错误是一个AggregateError实例, 这个实例对象的errors属性是一个数组, 包含了所有成员的错误
*  */
let alsoRejected = Promise.reject(Infinity)
Promise.any([resolved, rejected, alsoRejected]).then(function (results) {
  console.log(results)
})
Promise.any([resolved, alsoRejected]).catch(function (results) {
  console.log(results instanceof AggregateError) // true
  console.log(results.errors) // [-1, Infinity]
})

/* Promise.resolve()
*   有时需要将现有对象转为Promise对象, Promise.resolve() 方法就起到这个作用
*  */
const jsPromise = Promise.resolve($.ajax('/whatever.json'))
/* 上述代码将jQuery生成的deferred对象转为一个新的Promise对象 */
// Promise.resolve()等价于下面写法
Promise.resolve('foo')
// 等价于
new Promise(resolve => resolve('foo'))
/* Promise.resolve()方法的参数分为以下四种情况:
*   1. 参数是一个Promise实例: 那么Promise.resolve将不会做任何修改, 原封不动返回这个实例
*   2. 参数是一个thenable对象: (thenable对象指的是具有then方法的对象, 比如let thenable = {then: function(resolve, reject) {resolve(42)}})
*                            Promise.resolve()方法会将这个对象转为Promise对象, 然后立即执行thenable对象的then()方法
*  */
let thenable = {
  then: function(resolve, reject) {
    resolve(42)
  }
}
let p6 = Promise.resolve(thenable)
p6.then(function (value) {
  console.log(value) // 42
})
/* 上述代码中, thenable对象的then()方法执行后, 对象p6的状态就变成resolved, 从而立即执行then()方法指定的回调函数, 输出42 */
/*  3. 参数不是具有then() 方法的对象, 或者根本就不是对象: 如果参数是一个原始值, 或者是一个不具有then()方法的对象, 则Promise.resolve()方法返回一个新的Promise对象, 状态为resolved */
const p7 = Promise.resolve('Hello')
p7.then(function(s) {
  console.log(s) // Hello
})
/* 上述代码生成一个新的Promise对象的实例p7, 由于字符串Hello不属于异步操作(判断方法是字符串对象不具有then方法), 返回Promise实例的状态从一生成就是resolved
* ,所以回调函数会立即执行, Promise.resolve()方法的参数会同时传给回调函数 */
/*  4. 不带有任何参数: Promise.resolve() 方法允许调用时不带参数, 直接返回一个resolved状态Promise对象, 所以如果希望得到一个Promise对象比较方便的方法就是直接调用Promise.resolve()方法*/

/* Promise.reject(reason)方法也会返回一个新的Promise实例, 该实例的状态为rejected */
const p8 = Promise.reject('出错了')
// 等同于
const p9 =  new Promise(((resolve, reject) => reject('出错了')))
p9.then(null, function (s) {
  console.log(s) // 出错了
})

/* Promise.try()
*   实际开发中, 经常遇到一种情况: 不知道或者不想区分, 函数f时同步函数还是异步操作, 但是想用Promise来处理它, 因为这样就可以不管f是否包含异步操作
* ,都能用then方法指定下一步流程, 用catch来处理f抛出的错误, 一般就采用如下写法:
*  */
Promise.resolve().then(f)
/* 上述写法有一个缺点, 如果f时同步函数, 则它会在本轮事件循环的末尾执行 */
const f10 = () => console.log('now')
Promise.resolve().then(f10)
console.log('next')
// next
// now
/* 上述代码中,f是同步的, 但是用Promise包装之后, 变成了异步执行 */
/* 有没有一种方法, 可以让同步函数同步执行, 异步函数异步执行, 同时让他们具有同一的API呢, 有两种写法:
*   1. 用async函数来写
*  */
(async () => f10())()
console.log('next')
// now
// next
/* 上述代码中, 第二行是一个立即执行的匿名函数, 会立即执行里面的async函数, 因此如果f10是同步的, 就会得到同步的结果, 如果f是异步的, 就可以用then指定下一步 */
(async () => f())()
  .then()
/* 但是值得注意的是: async() => f()会吃掉f()抛出的错误, 所以如果想捕获错误要使用promise.catch方法 */
(async () => f())()
  .then()
  .catch()

/*  2. 使用new Promise() */
const f12 = () => console.log('now')
(
  () => new Promise(
    resolve => resolve(f12())
  )
)()
console.log('next')
// now
// next
/* 上述代码也是使用立即执行函数, 执行new Promise() 这种情况下, 同步函数也是同步执行的 */
/* 鉴于这是很常见的需求, 现在有一个提案, 提供Promise.try方法替代上面的写法 */
const f13 = () => console.log('now')
Promise.try(f13)
console.log('next')
/* 事实上, Promise.try存在已久, Promise库Bluebird, Q和when早就提供了这个方法 */
/* 由于Promise.try为所有的操作提供了统一的处理机制, 如果想用then方法管理流程, 最好都用Promise.try包装一下, 有许多好处, 其中之一就是可以更好地管理异常 */
/* 事实上, Promise.try就是模拟try代码块, 就像Promise.catch模拟的是catch代码块 */
</script>
</body>
</html>
